<?xml version="1.0" encoding="UTF-8"?>
<testng-results skipped="0" failed="2" ignored="0" total="7" passed="5">
  <reporter-output>
  </reporter-output>
  <suite name="Default suite" duration-ms="277" started-at="2017-05-24T19:06:13Z" finished-at="2017-05-24T19:06:14Z">
    <groups>
    </groups>
    <test name="Default test" duration-ms="277" started-at="2017-05-24T19:06:13Z" finished-at="2017-05-24T19:06:14Z">
      <class name="AssertScript.AssertDEmo1">
        <test-method status="FAIL" signature="assertTest1()[pri:0, instance:AssertScript.AssertDEmo1@6ea12c19]" name="assertTest1" duration-ms="39" started-at="2017-05-25T00:36:14Z" finished-at="2017-05-25T00:36:14Z">
          <exception class="java.lang.AssertionError">
            <message>
              <![CDATA[the value is not matched expected [3] but found [2]]]>
            </message>
            <full-stacktrace>
              <![CDATA[java.lang.AssertionError: the value is not matched expected [3] but found [2]
	at org.testng.Assert.fail(Assert.java:93)
	at org.testng.Assert.failNotEquals(Assert.java:512)
	at org.testng.Assert.assertEqualsImpl(Assert.java:134)
	at org.testng.Assert.assertEquals(Assert.java:115)
	at org.testng.Assert.assertEquals(Assert.java:388)
	at AssertScript.AssertDEmo1.assertTest1(AssertDEmo1.java:13)
	at sun.reflect.NativeMethodAccessorImpl.invoke0(Native Method)
	at sun.reflect.NativeMethodAccessorImpl.invoke(NativeMethodAccessorImpl.java:62)
	at sun.reflect.DelegatingMethodAccessorImpl.invoke(DelegatingMethodAccessorImpl.java:43)
	at java.lang.reflect.Method.invoke(Method.java:498)
	at org.testng.internal.MethodInvocationHelper.invokeMethod(MethodInvocationHelper.java:108)
	at org.testng.internal.Invoker.invokeMethod(Invoker.java:661)
	at org.testng.internal.Invoker.invokeTestMethod(Invoker.java:869)
	at org.testng.internal.Invoker.invokeTestMethods(Invoker.java:1193)
	at org.testng.internal.TestMethodWorker.invokeTestMethods(TestMethodWorker.java:126)
	at org.testng.internal.TestMethodWorker.run(TestMethodWorker.java:109)
	at org.testng.TestRunner.privateRun(TestRunner.java:744)
	at org.testng.TestRunner.run(TestRunner.java:602)
	at org.testng.SuiteRunner.runTest(SuiteRunner.java:380)
	at org.testng.SuiteRunner.runSequentially(SuiteRunner.java:375)
	at org.testng.SuiteRunner.privateRun(SuiteRunner.java:340)
	at org.testng.SuiteRunner.run(SuiteRunner.java:289)
	at org.testng.SuiteRunnerWorker.runSuite(SuiteRunnerWorker.java:52)
	at org.testng.SuiteRunnerWorker.run(SuiteRunnerWorker.java:86)
	at org.testng.TestNG.runSuitesSequentially(TestNG.java:1301)
	at org.testng.TestNG.runSuitesLocally(TestNG.java:1226)
	at org.testng.TestNG.runSuites(TestNG.java:1144)
	at org.testng.TestNG.run(TestNG.java:1115)
	at org.testng.remote.AbstractRemoteTestNG.run(AbstractRemoteTestNG.java:132)
	at org.testng.remote.RemoteTestNG.initAndRun(RemoteTestNG.java:230)
	at org.testng.remote.RemoteTestNG.main(RemoteTestNG.java:76)
]]>
            </full-stacktrace>
          </exception> <!-- java.lang.AssertionError -->
          <reporter-output>
          </reporter-output>
        </test-method> <!-- assertTest1 -->
        <test-method status="PASS" signature="assertTest2()[pri:0, instance:AssertScript.AssertDEmo1@6ea12c19]" name="assertTest2" duration-ms="5" started-at="2017-05-25T00:36:14Z" finished-at="2017-05-25T00:36:14Z">
          <reporter-output>
          </reporter-output>
        </test-method> <!-- assertTest2 -->
        <test-method status="PASS" signature="assertTest3()[pri:0, instance:AssertScript.AssertDEmo1@6ea12c19]" name="assertTest3" duration-ms="14" started-at="2017-05-25T00:36:14Z" finished-at="2017-05-25T00:36:14Z">
          <reporter-output>
          </reporter-output>
        </test-method> <!-- assertTest3 -->
        <test-method status="FAIL" signature="assertTest4()[pri:0, instance:AssertScript.AssertDEmo1@6ea12c19]" name="assertTest4" duration-ms="14" started-at="2017-05-25T00:36:14Z" finished-at="2017-05-25T00:36:14Z">
          <exception class="java.lang.AssertionError">
            <message>
              <![CDATA[value is not matching plz check the test case expected [20] but found [15]]]>
            </message>
            <full-stacktrace>
              <![CDATA[java.lang.AssertionError: value is not matching plz check the test case expected [20] but found [15]
	at org.testng.Assert.fail(Assert.java:93)
	at org.testng.Assert.failNotEquals(Assert.java:512)
	at org.testng.Assert.assertEqualsImpl(Assert.java:134)
	at org.testng.Assert.assertEquals(Assert.java:115)
	at org.testng.Assert.assertEquals(Assert.java:388)
	at AssertScript.AssertDEmo1.assertTest4(AssertDEmo1.java:33)
	at sun.reflect.NativeMethodAccessorImpl.invoke0(Native Method)
	at sun.reflect.NativeMethodAccessorImpl.invoke(NativeMethodAccessorImpl.java:62)
	at sun.reflect.DelegatingMethodAccessorImpl.invoke(DelegatingMethodAccessorImpl.java:43)
	at java.lang.reflect.Method.invoke(Method.java:498)
	at org.testng.internal.MethodInvocationHelper.invokeMethod(MethodInvocationHelper.java:108)
	at org.testng.internal.Invoker.invokeMethod(Invoker.java:661)
	at org.testng.internal.Invoker.invokeTestMethod(Invoker.java:869)
	at org.testng.internal.Invoker.invokeTestMethods(Invoker.java:1193)
	at org.testng.internal.TestMethodWorker.invokeTestMethods(TestMethodWorker.java:126)
	at org.testng.internal.TestMethodWorker.run(TestMethodWorker.java:109)
	at org.testng.TestRunner.privateRun(TestRunner.java:744)
	at org.testng.TestRunner.run(TestRunner.java:602)
	at org.testng.SuiteRunner.runTest(SuiteRunner.java:380)
	at org.testng.SuiteRunner.runSequentially(SuiteRunner.java:375)
	at org.testng.SuiteRunner.privateRun(SuiteRunner.java:340)
	at org.testng.SuiteRunner.run(SuiteRunner.java:289)
	at org.testng.SuiteRunnerWorker.runSuite(SuiteRunnerWorker.java:52)
	at org.testng.SuiteRunnerWorker.run(SuiteRunnerWorker.java:86)
	at org.testng.TestNG.runSuitesSequentially(TestNG.java:1301)
	at org.testng.TestNG.runSuitesLocally(TestNG.java:1226)
	at org.testng.TestNG.runSuites(TestNG.java:1144)
	at org.testng.TestNG.run(TestNG.java:1115)
	at org.testng.remote.AbstractRemoteTestNG.run(AbstractRemoteTestNG.java:132)
	at org.testng.remote.RemoteTestNG.initAndRun(RemoteTestNG.java:230)
	at org.testng.remote.RemoteTestNG.main(RemoteTestNG.java:76)
]]>
            </full-stacktrace>
          </exception> <!-- java.lang.AssertionError -->
          <reporter-output>
          </reporter-output>
        </test-method> <!-- assertTest4 -->
        <test-method status="PASS" signature="assertTest5()[pri:0, instance:AssertScript.AssertDEmo1@6ea12c19]" name="assertTest5" duration-ms="3" started-at="2017-05-25T00:36:14Z" finished-at="2017-05-25T00:36:14Z">
          <reporter-output>
          </reporter-output>
        </test-method> <!-- assertTest5 -->
        <test-method status="PASS" signature="assertTest6()[pri:0, instance:AssertScript.AssertDEmo1@6ea12c19]" name="assertTest6" duration-ms="8" started-at="2017-05-25T00:36:14Z" finished-at="2017-05-25T00:36:14Z">
          <reporter-output>
          </reporter-output>
        </test-method> <!-- assertTest6 -->
        <test-method status="PASS" signature="assertTest7()[pri:0, instance:AssertScript.AssertDEmo1@6ea12c19]" name="assertTest7" duration-ms="7" started-at="2017-05-25T00:36:14Z" finished-at="2017-05-25T00:36:14Z">
          <reporter-output>
          </reporter-output>
        </test-method> <!-- assertTest7 -->
      </class> <!-- AssertScript.AssertDEmo1 -->
    </test> <!-- Default test -->
  </suite> <!-- Default suite -->
</testng-results>
